Workbook

Sheet Resumo
A1: Projetos Rouanet 2027 – Revisão Art. 18 e planilhas orçamentárias (IN MinC 29/2026)
A2: Prazo de submissão: 31/10/2026 (IN 29, art. 5º). Valores orçados vêm das abas de cada projeto (fórmulas). Status/nota: revisão técnica dos documentos da pasta do Drive em 14/10/2026.
A4: # | B4: Projeto | C4: Frente | D4: Titular p/ carteira | E4: Tipo | F4: Valor pré-planejado | G4: Valor mínimo | H4: Valor total orçado | I4: Diferença | J4: Valor do projeto (base %) | K4: % Adm. | L4: % Acess./Divulg. | M4: % Captação | N4: Limites % e teto | O4: Produto principal – área / segmento (Anexo IV) | P4: Enquadr. | Q4: Campos SALIC OK | R4: PARCIAL | S4: AUSENTE | T4: Nota (0-10) | U4: Status | V4: Pendências críticas
A5: P01 | B5: Escola de Ofícios do Espetáculo | C5: 01. Cultura | D5: Educare | E5: PJ | F5: 500000 | G5: 100000 | H5: ='P01 Escola de Ofícios do Espetá'!B20 -> 499745 | I5: =H5-F5 -> -255 | J5: ='P01 Escola de Ofícios do Espetá'!B16 -> 393500 | K5: ='P01 Escola de Ofícios do Espetá'!C17 -> 0.08 | L5: ='P01 Escola de Ofícios do Espetá'!C18 -> 0.09 | M5: ='P01 Escola de Ofícios do Espetá'!C19 -> 0.1 | N5: =IF(AND('P01 Escola de Ofícios do Espetá'!E17="OK",'P01 Escola de Ofícios do Espetá'!E18="OK",'P01 Escola de Ofícios do Espetá'!E19="OK",'P01 Escola de Ofícios do Espetá'!E22="OK"),"OK","EXCEDE") -> OK | O5: Curso/Oficina – ciclo formativo de iniciação aos ofícios técnicos e criativos das artes cênicas (9 turmas x 24h, 270 vagas, 3 núcleos) – Artes Cênicas / Empreend Ações Educ-Cult/Capacitação/Treinamento | P5: Art. 18 | Q5: 5 | R5: 13 | S5: 3 | T5: 5 | U5: Ajustes importantes | V5: • Documentação jurídica da Educare (cartão CNPJ com CNAE cultural compatível, contrato social, representante) – sem isso o SALIC não admite. • Portfólio de atuação cultural da Educare (obrigatório para projeto de R$ 500 mil). • Projeto pedagógico formal com currículo da coordenadora pedagógica e plano de execução com carga horária e conteúdo programático por turma (Anexo II 7.2/7.3), incluindo a matriz núcleo x formação. • Cartas de anuência dos 3 núcleos e do local da mostra; definição do grupo teatral parceiro com autorização autoral.
A6: P02 | B6: Mestres e Aprendizes | C6: 01. Cultura | D6: Aver Mídia | E6: PJ | F6: 400000 | G6: 80000 | H6: ='P02 Mestres e Aprendizes'!B20 -> 399996.75 | I6: =H6-F6 -> -3.25 | J6: ='P02 Mestres e Aprendizes'!B16 -> 310075 | K6: ='P02 Mestres e Aprendizes'!C17 -> 0.08 | L6: ='P02 Mestres e Aprendizes'!C18 -> 0.11 | M6: ='P02 Mestres e Aprendizes'!C19 -> 0.1 | N6: =IF(AND('P02 Mestres e Aprendizes'!E17="OK",'P02 Mestres e Aprendizes'!E18="OK",'P02 Mestres e Aprendizes'!E19="OK",'P02 Mestres e Aprendizes'!E22="OK"),"OK","EXCEDE") -> OK | O6: Percursos continuados de transmissão de saberes tradicionais conduzidos por 4 mestres (4 turmas x 48h, 120 aprendizes) – Patrimônio Cultural / Salvaguarda do patrimônio cultural imaterial | P6: Art. 18 | Q6: 7 | R6: 11 | S6: 3 | T6: 4 | U6: Ajustes importantes | V6: • Selecionar e formalizar os 4 mestres (cartas de anuência) e, quando o saber for coletivo, a anuência da comunidade detentora (Anexo II 8.1.3). • Dossiê por saber com relatório de reconhecido valor cultural, identificação e relatório do bem (Anexo II 8.1.1, 8.1.2.1, 8.1.4, 8.1.5) – ou acionar o Plano B (Artes Visuais – Ações Educ-Cult). • Documentação PJ da Aver Mídia com CNAE compatível e portfólio cultural. • Espaços das 4 turmas e da exposição com anuência.
A7: P03 | B7: Cultura Viva nas Vilas | C7: 01. Cultura | D7: IHV | E7: PJ | F7: 200000 | G7: 40000 | H7: ='P03 Cultura Viva nas Vilas'!B20 -> 199953.87 | I7: =H7-F7 -> -46.13 | J7: ='P03 Cultura Viva nas Vilas'!B16 -> 155003 | K7: ='P03 Cultura Viva nas Vilas'!C17 -> 0.07 | L7: ='P03 Cultura Viva nas Vilas'!C18 -> 0.12 | M7: ='P03 Cultura Viva nas Vilas'!C19 -> 0.1 | N7: =IF(AND('P03 Cultura Viva nas Vilas'!E17="OK",'P03 Cultura Viva nas Vilas'!E18="OK",'P03 Cultura Viva nas Vilas'!E19="OK",'P03 Cultura Viva nas Vilas'!E22="OK"),"OK","EXCEDE") -> OK | O7: Oficinas de formação artística em cultura urbana – música e musicalidade, grafite e audiovisual (8 oficinas x 24h, 200 participantes) – Artes Visuais / Empreend Ações Educ-Cult/Capacitação/Treinamento | P7: Art. 18 | Q7: 7 | R7: 10 | S7: 4 | T7: 4 | U7: Ajustes importantes | V7: • Regularidade cadastral do IHV (CNPJ ativo, estatuto, ata, representante, CNAE cultural) e padronização do nome/sigla (IHV x IHGV). • Confirmar a função de Ado Viana no IHV e o histórico do IHV no Pronac (dispensa de portfólio e art. 15) – risco de questionamento de carteira/fracionamento com P05 e P16. • Plano de execução com carga horária e conteúdo programático das 8 oficinas e ficha técnica nominal (curadoria + ≥6 oficineiros). • Cartas de anuência dos 4 espaços (incluindo solução para 12–14 anos no Eldorado) e autorizações para painéis de grafite.
A8: P04 | B8: Cena Mineira em Movimento | C8: 01. Cultura | D8: Mobox | E8: PJ | F8: 900000 | G8: 180000 | H8: ='P04 Cena Mineira em Movimento'!B20 -> 899987.85 | I8: =H8-F8 -> -12.15 | J8: ='P04 Cena Mineira em Movimento'!B16 -> 697665 | K8: ='P04 Cena Mineira em Movimento'!C17 -> 0.09 | L8: ='P04 Cena Mineira em Movimento'!C18 -> 0.1 | M8: ='P04 Cena Mineira em Movimento'!C19 -> 0.1 | N8: =IF(AND('P04 Cena Mineira em Movimento'!E17="OK",'P04 Cena Mineira em Movimento'!E18="OK",'P04 Cena Mineira em Movimento'!E19="OK",'P04 Cena Mineira em Movimento'!E22="OK"),"OK","EXCEDE") -> OK | O8: Circulação de 4 espetáculos mineiros de teatro/dança – 24 apresentações gratuitas em 12 municípios – Artes Cênicas / Apresentação ou Performance de Teatro | P8: Art. 18 | Q8: 5 | R8: 12 | S8: 4 | T8: 5 | U8: Ajustes importantes | V8: • Dados jurídicos da Mobox (razão social, CNPJ, CNAE, representante) e portfólio. • Fechar 24 apresentações/24 oficinas e a matriz espetáculo x município (ou outro número), refletindo metas e planilha. • Pré-selecionar (por convite) os 4 espetáculos ou parte deles com sinopse, ficha técnica, currículos e autorização do autor do texto – sem isso o Anexo II 3.3 fica descoberto. • Anuências das 12 prefeituras/equipamentos com ficha técnica e lotação.
A9: P05 | B9: Sons do Congado | C9: 01. Cultura | D9: Ado Viana | E9: PF | F9: 300000 | G9: 60000 | H9: ='P05 Sons do Congado'!B20 -> 299998.13 | I9: =H9-F9 -> -1.87 | J9: ='P05 Sons do Congado'!B16 -> 236219 | K9: ='P05 Sons do Congado'!C17 -> 0.07 | L9: ='P05 Sons do Congado'!C18 -> 0.1 | M9: ='P05 Sons do Congado'!C19 -> 0.1 | N9: =IF(AND('P05 Sons do Congado'!E17="OK",'P05 Sons do Congado'!E18="OK",'P05 Sons do Congado'!E19="OK",'P05 Sons do Congado'!E22="OK"),"OK","EXCEDE") -> OK | O9: Álbum Sons do Congado como registro sonoro de salvaguarda: gravação de campo com 4 guardas (12 faixas), repertório e limites de registro definidos pelos mestres, devolução às comunidades e difusão gratuita. – Patrimônio Cultural / Salvaguarda do patrimônio cultural imaterial | P9: Art. 18 | Q9: 3 | R9: 12 | S9: 6 | T9: 4 | U9: Ajustes importantes | V9: • Definir e cadastrar o proponente PF (CPF, endereço, portfólio de Ado Viana). Confirmar que a carteira P05 + P16 = R$ 500 mil não será ultrapassada. • Obter as declarações de anuência das guardas/comunidades detentoras e o relatório de reconhecido valor cultural (Anexo II, 8.1.2.1 e 8.1.3). Sem isso o Iphan não admite a proposta. • Fechar a lista nominal de guardas, mestres e municípios e as especificações técnicas (12 faixas, 6 oficinas de 4h, minidoc de 15 min, apresentação). • Ficha técnica com currículos, em especial do articulador comunitário/coordenador com experiência comprovada junto às comunidades (8.1.6) e da direção musical.
A10: P06 | B10: Mural Minas | C10: 01. Cultura | D10: Morsa | E10: PJ | F10: 750000 | G10: 150000 | H10: ='P06 Mural Minas'!B20 -> 749993.42 | I10: =H10-F10 -> -6.58 | J10: ='P06 Mural Minas'!B16 -> 590546 | K10: ='P06 Mural Minas'!C17 -> 0.08 | L10: ='P06 Mural Minas'!C18 -> 0.09 | M10: ='P06 Mural Minas'!C19 -> 0.1 | N10: =IF(AND('P06 Mural Minas'!E17="OK",'P06 Mural Minas'!E18="OK",'P06 Mural Minas'!E19="OK",'P06 Mural Minas'!E22="OK"),"OK","EXCEDE") -> OK | O10: 6 murais de arte urbana (~180 m² no total) criados com as turmas e artistas-educadores, em exposição pública permanente e gratuita em BH, Contagem e Santa Luzia. – Artes Visuais / Exposição Cultural / Artística | P10: Art. 18 | Q10: 8 | R10: 10 | S10: 3 | T10: 5 | U10: Ajustes importantes | V10: • CNAE da Morsa: incluir CNAE secundário cultural compatível com Artes Visuais/ensino de arte (o principal é edição de jornais), senão o SALIC inadmite. • Reescrever o documento (hoje no modelo LEIC) para o SALIC: área Artes Visuais, segmento Exposição Cultural/Artística, Art. 18; retirar a prática de 'pixo' do objeto. • Definir as 6 superfícies com anuência/termo de cessão e corrigir a área (180 m² x 80 m²). Decidir 6 ou 9 murais. • Equipe com currículos e plano pedagógico com carga horária e conteúdo programático (Anexo II, 4.1 e 7.3).
A11: P07 | B11: Concertos nas Praças do Interior (documentos: 'Concertos na Praça') | C11: 01. Cultura | D11: Túlio Gama | E11: PF | F11: 500000 | G11: 100000 | H11: ='P07 Concertos nas Praças do Int'!B20 -> 499955.82 | I11: =H11-F11 -> -44.18 | J11: ='P07 Concertos nas Praças do Int'!B16 -> 393666 | K11: ='P07 Concertos nas Praças do Int'!C17 -> 0.07 | L11: ='P07 Concertos nas Praças do Int'!C18 -> 0.1 | M11: ='P07 Concertos nas Praças do Int'!C19 -> 0.1 | N11: =IF(AND('P07 Concertos nas Praças do Int'!E17="OK",'P07 Concertos nas Praças do Int'!E18="OK",'P07 Concertos nas Praças do Int'!E19="OK",'P07 Concertos nas Praças do Int'!E22="OK"),"OK","EXCEDE") -> OK | O11: Circuito de 8 concertos gratuitos de música instrumental/de concerto com formação de câmara (8 músicos + regente) e aberturas regionais instrumentais/corais. – Música / Apresentação/Gravação de Música Instrumental (alternativa: Apresentação/Gravação de Música Erudita) | P11: Art. 18 | Q11: 7 | R11: 11 | S11: 3 | T11: 5 | U11: Ajustes importantes | V11: • Confirmar Túlio Gama (PF) como proponente, corrigir a pasta 'PRO SP' e conferir a carteira: com P07 a R$ 500 mil, P12 vai para a LEIC e P08 fica com a ProSP. • Definir formação principal (nº de músicos), regente/diretor artístico e grupos regionais, com currículos (Anexo II, 5.1). • Escolher os municípios/praças e obter anuências municipais com a lista do que cada prefeitura cede (energia, segurança, banheiros, gradil). Sem isso, 8 concertos não cabem em R$ 500 mil. • Fechar a planilha com cotações (palco, som, ônibus, hospedagem) e a simulação do ECAD; dividir a estrutura entre fornecedores para respeitar o limite de 20%.
A12: P08 | B12: Sabores de Minas – Circuito de Cultura Alimentar, Memória e Patrimônio de Minas Gerais | C12: 01. Cultura | D12: PRO SP | E12: PJ | F12: 600000 | G12: 120000 | H12: ='P08 Sabores de Minas – Circuito'!B20 -> 599985.45 | I12: =H12-F12 -> -14.55 | J12: ='P08 Sabores de Minas – Circuito'!B16 -> 465105 | K12: ='P08 Sabores de Minas – Circuito'!C17 -> 0.08 | L12: ='P08 Sabores de Minas – Circuito'!C18 -> 0.11 | M12: ='P08 Sabores de Minas – Circuito'!C19 -> 0.1 | N12: =IF(AND('P08 Sabores de Minas – Circuito'!E17="OK",'P08 Sabores de Minas – Circuito'!E18="OK",'P08 Sabores de Minas – Circuito'!E19="OK",'P08 Sabores de Minas – Circuito'!E22="OK"),"OK","EXCEDE") -> OK | O12: Encontros de transmissão de saberes da cultura alimentar tradicional mineira com mestres e detentores (cozinhas de mestres, oficinas, 'Cozinha de Memórias' com escolas e rodas de conversa) em 4 etapas municipais, como ação de salvaguarda. – Patrimônio Cultural / Salvaguarda do patrimônio cultural imaterial | P12: Risco | Q12: 4 | R12: 15 | S12: 2 | T12: 3 | U12: Não submeter como está | V12: • Reestruturar o objeto de 'festival gastronômico' para salvaguarda de saberes e modos de fazer tradicionais (Patrimônio/Salvaguarda, Art. 18). Do contrário, o enquadramento é Art. 26 e há glosa de custos (IN, art. 18). • Confirmar o proponente ProSP (CNPJ, CNAE compatível, representante) e corrigir a pasta 'Túlio Gama'. Como PF de Túlio, o projeto é inviável (teto R$ 500 mil e carteira já usada por P07). • Reunir o Anexo II, item 8: identificação dos saberes/bens, registro ou relatório de reconhecido valor, anuências dos detentores/comunidades e ficha técnica com experiência junto às comunidades. • Regulamentar a feira sem taxa e sem receita para o projeto, ou declarar a receita e aplicar o art. 44.
A13: P09 | B13: Auto de Natal Mineiro | C13: 02. Natal | D13: Armind | E13: A confirmar | F13: 700000 | G13: 140000 | H13: ='P09 Auto de Natal Mineiro'!B20 -> 699999.84 | I13: =H13-F13 -> -0.16 | J13: ='P09 Auto de Natal Mineiro'!B16 -> 564516 | K13: ='P09 Auto de Natal Mineiro'!C17 -> 0.07 | L13: ='P09 Auto de Natal Mineiro'!C18 -> 0.07 | M13: ='P09 Auto de Natal Mineiro'!C19 -> 0.1 | N13: =IF(AND('P09 Auto de Natal Mineiro'!E17="OK",'P09 Auto de Natal Mineiro'!E18="OK",'P09 Auto de Natal Mineiro'!E19="OK",'P09 Auto de Natal Mineiro'!E22="OK"),"OK","EXCEDE") -> EXCEDE | O13: Espetáculo teatral-musical Auto de Natal Mineiro – criação e circulação (10 apresentações gratuitas) – Artes Cênicas / Teatro Musical (c/ dramaturgia, danças e canções) – alternativa equivalente: Apresentação ou Performance de Teatro | P13: Art. 18 | Q13: 7 | R13: 11 | S13: 3 | T13: 5 | U13: Ajustes importantes | V13: • Resolver a sobreposição com o P10 (mesmo proponente Arminde e mesmo objeto 'Auto de Natal' em nov–dez/2027) antes de submeter. Sem isso há risco de indeferimento por fracionamento ou duplicidade e de custos de criação contados duas vezes. • Natureza jurídica e dossiê da Arminde (PF, MEI ou PJ; CNPJ e CNAE; portfólio obrigatório por ser > R$ 200 mil). Se for PF, o projeto tem de baixar para ≤ R$ 500 mil. • Ficha técnica com currículos, autor do texto com contrato ou anuência (Anexo II 3.1 e 3.3) e sinopse. • Fechar os 8 municípios e as praças com manifestação das prefeituras, mais o calendário real.
A14: P10 | B14: Natal nas Cidades Mineiras | C14: 02. Natal | D14: Gustavo Ribeiro | E14: A confirmar | F14: 500000 | G14: 100000 | H14: ='P10 Natal nas Cidades Mineiras'!B20 -> 499996.16 | I14: =H14-F14 -> -3.84 | J14: ='P10 Natal nas Cidades Mineiras'!B16 -> 390622 | K14: ='P10 Natal nas Cidades Mineiras'!C17 -> 0.08 | L14: ='P10 Natal nas Cidades Mineiras'!C18 -> 0.1 | M14: ='P10 Natal nas Cidades Mineiras'!C19 -> 0.1 | N14: =IF(AND('P10 Natal nas Cidades Mineiras'!E17="OK",'P10 Natal nas Cidades Mineiras'!E18="OK",'P10 Natal nas Cidades Mineiras'!E19="OK",'P10 Natal nas Cidades Mineiras'!E22="OK"),"OK","EXCEDE") -> OK | O14: Espetáculo Auto de Natal – 5 apresentações gratuitas em praças (criação/adaptação e circulação) – Artes Cênicas / Apresentação ou Performance de Teatro | P14: Art. 18 | Q14: 7 | R14: 11 | S14: 3 | T14: 3 | U14: Não submeter como está | V14: • Resolver a duplicidade com o P09: mesmo proponente (Arminde) e mesmo objeto (Auto de Natal gratuito em praças de MG em nov–dez/2027). Do jeito que está, o projeto não deve ser submetido à Rouanet em paralelo ao P09. • Definir o titular (Arminde PJ ou Gustavo Ribeiro PF) e reunir CNPJ, CNAE, contrato social e portfólio. A planilha e os documentos divergem. • Anuências das 5 prefeituras e autorizações de patrimônio nas cidades históricas, com praças definidas. • Ficha técnica e sinopse do Auto, com anuência do autor.
A15: P11 | B15: Festa Junina 2027 – Saberes e Tradições do Forró | C15: 03. Festas Populares | D15: Mobox | E15: PJ | F15: 800000 | G15: 160000 | H15: ='P11 Festa Junina 2027 – Saberes'!B20 -> 799988.75 | I15: =H15-F15 -> -11.25 | J15: ='P11 Festa Junina 2027 – Saberes'!B16 -> 639991 | K15: ='P11 Festa Junina 2027 – Saberes'!C17 -> 0.06 | L15: ='P11 Festa Junina 2027 – Saberes'!C18 -> 0.09 | M15: ='P11 Festa Junina 2027 – Saberes'!C19 -> 0.1 | N15: =IF(AND('P11 Festa Junina 2027 – Saberes'!E17="OK",'P11 Festa Junina 2027 – Saberes'!E18="OK",'P11 Festa Junina 2027 – Saberes'!E19="OK",'P11 Festa Junina 2027 – Saberes'!E22="OK"),"OK","EXCEDE") -> OK | O15: Festival/Festa: circuito Festa Junina – Saberes e Tradições do Forró (4 municípios, 8 dias). Pelo art. 46, parágrafo único, o enquadramento é dado pelo secundário de maior valor: as 16 apresentações das Matrizes Tradicionais do Forró – Patrimônio Cultural / Salvaguarda do patrimônio cultural imaterial (produto Festival, Bienal, Festa ou Feira) | P15: Art. 18 | Q15: 8 | R15: 11 | S15: 2 | T15: 6 | U15: Ajustes importantes | V15: • Anuência da comunidade detentora das Matrizes Tradicionais do Forró (grupos e coletivos forrozeiros de MG), relatório do bem e comprovante do registro Iphan (Anexo II 8.1.1–8.1.5 e 8.8). Sem isso o enquadramento em Patrimônio não se sustenta. • Fixar no SALIC o segmento das apresentações (Salvaguarda do PCI, ou Música Regional) e retirar o 'sertanejo raiz', para que o secundário de maior valor garanta o Art. 18. • Confirmar municípios, espaços e datas com cartas das prefeituras, incluindo o apoio assumido na planilha: energia da rede, sanitários do local e policiamento. • Cadastro, CNAE e portfólio da Mobox.
A16: P12 | B16: Bloco do Nerd / Carnaval (Bloco Nerd) | C16: 03. Festas Populares | D16: Túlio Gama | E16: PF | F16: 250000 | G16: 50000 | H16: ='P12 Bloco do Nerd Carnaval (Bl'!B20 -> 249999.5 | I16: =H16-F16 -> -0.5 | J16: ='P12 Bloco do Nerd Carnaval (Bl'!B16 -> 196850 | K16: ='P12 Bloco do Nerd Carnaval (Bl'!C17 -> 0.06 | L16: ='P12 Bloco do Nerd Carnaval (Bl'!C18 -> 0.11 | M16: ='P12 Bloco do Nerd Carnaval (Bl'!C19 -> 0.1 | N16: =IF(AND('P12 Bloco do Nerd Carnaval (Bl'!E17="OK",'P12 Bloco do Nerd Carnaval (Bl'!E18="OK",'P12 Bloco do Nerd Carnaval (Bl'!E19="OK",'P12 Bloco do Nerd Carnaval (Bl'!E22="OK"),"OK","EXCEDE") -> OK | O16: Desfile festivo – cortejo carnavalesco Bloco Nerd (com ensaios abertos e lançamento) – Artes Cênicas / Desfiles festivos de caráter musical e cênico | P16: Art. 18 | Q16: 7 | R16: 12 | S16: 2 | T16: 3 | U16: Não submeter como está | V16: • Escolher qual projeto do Túlio vai à Rouanet. P07 + P12 como PF somam R$ 750 mil e violam a carteira de R$ 500 mil (art. 10, I). Conferir também o vínculo de Túlio com a Morsa (art. 15) e com o P08. • Titular formal: PF Túlio ou Morsa, sendo que o CNAE da Morsa ('edição de jornais') é incompatível. Reunir o portfólio documentado (obrigatório acima de R$ 200 mil). • Edição: o Carnaval 2027 é inviável na Rouanet. Reescrever para o Carnaval 2028, o que permite submeter na janela de 2027. • Direitos: nome 'Bloco Nerd' (conflito com outro bloco), licenças de arranjo dos temas, personagens NXP e eliminação do playback.
A17: P13 | B17: Skate e Arte Urbana (Circuito Skate & Rua) | C17: Esporte com cultura | D17: ESIP | E17: PJ | F17: 350000 | G17: 70000 | H17: ='P13 Skate e Arte Urbana (Circui'!B20 -> 349997.76 | I17: =H17-F17 -> -2.24 | J17: ='P13 Skate e Arte Urbana (Circui'!B16 -> 277776 | K17: ='P13 Skate e Arte Urbana (Circui'!C17 -> 0.06 | L17: ='P13 Skate e Arte Urbana (Circui'!C18 -> 0.1 | M17: ='P13 Skate e Arte Urbana (Circui'!C19 -> 0.1 | N17: =IF(AND('P13 Skate e Arte Urbana (Circui'!E17="OK",'P13 Skate e Arte Urbana (Circui'!E18="OK",'P13 Skate e Arte Urbana (Circui'!E19="OK",'P13 Skate e Arte Urbana (Circui'!E22="OK"),"OK","EXCEDE") -> OK | O17: Oficinas de arte urbana (grafite) com criação coletiva de 4 murais permanentes em pistas públicas de skate da RMBH – Artes Visuais / Empreend Ações Educ-Cult/Capacitação/Treinamento | P17: Art. 18 | Q17: 1 | R17: 16 | S17: 4 | T17: 3 | U17: Ajustes importantes | V17: • Reescrever o projeto inteiro com objeto cultural. O texto atual (LIE, com 'predominância esportiva') é inadmissível no SALIC e teria quase todo o orçamento glosado pelo art. 18 da IN. • ESIP: comprovar CNPJ com CNAE cultural compatível com Artes Visuais/Cênicas, estatuto, ata e portfólio de atuação CULTURAL (valor > R$ 200 mil). Sem isso, a proposta não é admitida. • Anuências das 4 pistas, incluindo autorização expressa para pintura mural permanente (superfície, tema, conservação), e cartas de coletivos locais de hip-hop/grafite. • Ficha técnica nominada (curadoria de arte urbana, muralistas, arte-educadores de grafite e breaking, DJ/MC, grupo de breaking) com currículos, e projeto pedagógico com carga horária e conteúdo (Anexo II 7.2/7.3).
A18: P14 | B18: Capoeira: Roda de Minas | C18: Esporte com cultura | D18: ESIP | E18: PJ | F18: 300000 | G18: 60000 | H18: ='P14 Capoeira Roda de Minas'!B20 -> 299993.75 | I18: =H18-F18 -> -6.25 | J18: ='P14 Capoeira Roda de Minas'!B16 -> 239995 | K18: ='P14 Capoeira Roda de Minas'!C17 -> 0.06 | L18: ='P14 Capoeira Roda de Minas'!C18 -> 0.09 | M18: ='P14 Capoeira Roda de Minas'!C19 -> 0.1 | N18: =IF(AND('P14 Capoeira Roda de Minas'!E17="OK",'P14 Capoeira Roda de Minas'!E18="OK",'P14 Capoeira Roda de Minas'!E19="OK",'P14 Capoeira Roda de Minas'!E22="OK"),"OK","EXCEDE") -> OK | O18: Núcleos de formação em capoeira: 4 núcleos, 100 participantes, 16 encontros de 2 h com mestres (fundamentos, musicalidade, história, oralidade) – Artes Cênicas / Apresentação de Dança ou Ação Educativa: Capoeira | P18: Art. 18 | Q18: 6 | R18: 11 | S18: 4 | T18: 5 | U18: Ajustes importantes | V18: • ESIP: CNPJ com CNAE cultural compatível com Artes Cênicas, estatuto com finalidade cultural, ata, certidões e portfólio cultural (valor > R$ 200 mil). O próprio documento classifica isso como pendência CRÍTICA nº 1. • Definir os 2 territórios restantes e os 4 espaços, com cartas de anuência e condições de acessibilidade. Confirmar ou retirar o núcleo quilombola (só citar com anuência formal). • Nominar os mestres dos núcleos e os convidados do Encontro, com currículos e cartas de aceite. Elaborar o projeto pedagógico dos 16 encontros (Anexo II, item 7). • Retirar a narrativa esportiva da versão SALIC e resolver a relação com a lei estadual do esporte (duplicidade de fontes; plano do cliente é LEIC-MG).
A19: P15 | B19: Riso que Cura | C19: Saúde | D19: Aver Mídia | E19: PJ | F19: 450000 | G19: 90000 | H19: ='P15 Riso que Cura'!B20 -> 449675 | I19: =H19-F19 -> -325 | J19: ='P15 Riso que Cura'!B16 -> 359740 | K19: ='P15 Riso que Cura'!C17 -> 0.06 | L19: ='P15 Riso que Cura'!C18 -> 0.09 | M19: ='P15 Riso que Cura'!C19 -> 0.1 | N19: =IF(AND('P15 Riso que Cura'!E17="OK",'P15 Riso que Cura'!E18="OK",'P15 Riso que Cura'!E19="OK",'P15 Riso que Cura'!E22="OK"),"OK","EXCEDE") -> OK | O19: Circulação de performances/intervenções de palhaçaria em hospitais (144 visitas em duplas, 6 hospitais) – Artes Cênicas / Performance de Circo, Clown e Ilusionismo | P19: Art. 18 | Q19: 7 | R19: 10 | S19: 4 | T19: 6 | U19: Ajustes importantes | V19: • Dados jurídicos da Aver Mídia (CNPJ, atos, representante) e CNAE compatível com artes cênicas – risco de inabilitação se o CNAE for só de mídia/publicidade. • Portfólio cultural comprovável da Aver Mídia (obrigatório para valor > R$ 200 mil). • Cartas de interesse/anuência dos 6 hospitais (nome, setor, contato) – sem elas o território e o plano de distribuição são fictícios. • Validação da escala: 144 visitas só cabem em R$ 450 mil com cachê de R$ 400/turno, coordenação acumulada e captação ~9% (ver planilha); confirmar com artistas antes de congelar.
A20: P16 | B20: Música nos Hospitais | C20: Saúde | D20: Ado Viana | E20: PF | F20: 200000 | G20: 40000 | H20: ='P16 Música nos Hospitais'!B20 -> 199888 | I20: =H20-F20 -> -112 | J20: ='P16 Música nos Hospitais'!B16 -> 153760 | K20: ='P16 Música nos Hospitais'!C17 -> 0.08 | L20: ='P16 Música nos Hospitais'!C18 -> 0.12 | M20: ='P16 Música nos Hospitais'!C19 -> 0.1 | N20: =IF(AND('P16 Música nos Hospitais'!E17="OK",'P16 Música nos Hospitais'!E18="OK",'P16 Música nos Hospitais'!E19="OK",'P16 Música nos Hospitais'!E22="OK"),"OK","EXCEDE") -> OK | O20: Apresentações de música instrumental/regional mineira (trio acústico) em instituições de saúde – 30 apresentações – Música / Apresentação/Gravação de Música Instrumental (alternativa: Música Regional) | P20: Risco | Q20: 6 | R20: 10 | S20: 5 | T20: 5 | U20: Ajustes importantes | V20: • Decisão curatorial (formação instrumental/regional) – sem ela o produto principal tende a Art. 26 (música popular cantada). • Carteira PF no limite: P05 (R$ 300 mil) + P16 (R$ 200 mil) = R$ 500 mil e 2 projetos; confirmar que não há outro projeto ativo e vínculos com PJ (art. 15). • Anuências das 6 instituições (nenhuma indicada). • Documentos do proponente PF e equipe nominal (currículos de músicos e educador) + projeto pedagógico das oficinas.
A21: P17 | B21: Corpo em Cena | C21: Saúde | D21: Amanda Lourenço | E21: A confirmar | F21: 200000 | G21: 40000 | H21: ='P17 Corpo em Cena'!B20 -> 199986.9 | I21: =H21-F21 -> -13.1 | J21: ='P17 Corpo em Cena'!B16 -> 157470 | K21: ='P17 Corpo em Cena'!C17 -> 0.08 | L21: ='P17 Corpo em Cena'!C18 -> 0.09 | M21: ='P17 Corpo em Cena'!C19 -> 0.1 | N21: =IF(AND('P17 Corpo em Cena'!E17="OK",'P17 Corpo em Cena'!E18="OK",'P17 Corpo em Cena'!E19="OK",'P17 Corpo em Cena'!E22="OK"),"OK","EXCEDE") -> OK | O21: Oficinas de dança, expressão corporal e artes visuais com criação coletiva (3 núcleos, 48 encontros, 96 h) – Artes Cênicas / Empreendimento de Ações Educativo-Culturais/Capacitação/Treinamento (dança) | P21: Art. 18 | Q21: 8 | R21: 10 | S21: 3 | T21: 6 | U21: Ajustes importantes | V21: • Definir o proponente formal (PF Amanda Lourenço ou PJ com CNAE cultural) – sem ele não há inscrição. • Escolher o 3º município e obter anuências dos 3 espaços de oficinas e do local da apresentação principal em BH. • Ficha técnica nominal e projeto pedagógico formal (carga horária e conteúdo – Anexo II). • Datas civis do cronograma e decisão IFC x Rouanet sem dupla captação.
A22: P18 | B22: Arte e Envelhecimento Ativo | C22: Saúde | D22: Educare | E22: PJ | F22: 250000 | G22: 50000 | H22: ='P18 Arte e Envelhecimento Ativo'!B20 -> 249958.14 | I22: =H22-F22 -> -41.86 | J22: ='P18 Arte e Envelhecimento Ativo'!B16 -> 193766 | K22: ='P18 Arte e Envelhecimento Ativo'!C17 -> 0.08 | L22: ='P18 Arte e Envelhecimento Ativo'!C18 -> 0.11 | M22: ='P18 Arte e Envelhecimento Ativo'!C19 -> 0.1 | N22: =IF(AND('P18 Arte e Envelhecimento Ativo'!E17="OK",'P18 Arte e Envelhecimento Ativo'!E18="OK",'P18 Arte e Envelhecimento Ativo'!E19="OK",'P18 Arte e Envelhecimento Ativo'!E22="OK"),"OK","EXCEDE") -> OK | O22: Oficinas continuadas de dança adaptada para pessoas idosas (72 encontros) com direção artístico-pedagógica – Artes Cênicas / Empreendimento de Ações Educativo-Culturais/Capacitação/Treinamento (dança) | P22: Art. 18 | Q22: 9 | R22: 8 | S22: 4 | T22: 7 | U22: Ajustes importantes | V22: • Confirmar a Educare como proponente (CNPJ, CNAE cultural compatível, portfólio – obrigatório acima de R$ 200 mil). • Anuência das 6 instituições (centros de convivência/ILPIs) com calendário de 24 semanas. • Ficha técnica nominal (direção, regente, arte-educador de dança, formador) e projeto pedagógico formal. • Datas civis e decisão sobre fonte complementar (IFC) sem dupla captação.
A23: P19 | B23: Acelera Minas – formação de kart | C23: Esporte com cultura | D23: Rafael Tose | E23: A confirmar | F23: 450000 | G23: 90000 | H23: ='P19 Acelera Minas – formação de'!B20 -> 449999.72 | I23: =H23-F23 -> -0.28 | J23: ='P19 Acelera Minas – formação de'!B16 -> 362903 | K23: ='P19 Acelera Minas – formação de'!C17 -> 0.06 | L23: ='P19 Acelera Minas – formação de'!C18 -> 0.08 | M23: ='P19 Acelera Minas – formação de'!C19 -> 0.1 | N23: =IF(AND('P19 Acelera Minas – formação de'!E17="OK",'P19 Acelera Minas – formação de'!E18="OK",'P19 Acelera Minas – formação de'!E19="OK",'P19 Acelera Minas – formação de'!E22="OK"),"OK","EXCEDE") -> OK | O23: [REFORMULAÇÃO – referência] Laboratório de formação audiovisual para 80 adolescentes (4 turmas de 20, 80 h cada) de Juatuba e Santa Luzia – Audiovisual / Ações de capacitação e treinamento de pessoal | P23: Risco | Q23: 0 | R23: 17 | S23: 4 | T23: 1 | U23: Não submeter como está | V23: • NÃO SUBMETER À ROUANET: o objeto (escola de kart) é esportivo, sem segmento no Anexo IV, e o orçamento seria integralmente glosado (IN art. 18). A planilha esportiva original não é aceitável. • Encaminhar para a Lei de Incentivo ao Esporte (Lei 11.438/2006) ou para a Lei Estadual de Incentivo ao Esporte de MG (Lei 20.824/2013), com uma OSC esportiva como proponente. • Valor incompatível: o documento pede R$ 2.434.400, a planilha do cliente prevê R$ 450 mil. Redimensionar em qualquer mecanismo. • Proponente indefinido ('[Nome da OSC]' x Rafael Tose). Se Rafael Tose for PF, só cabe um entre P19 e P21 na Rouanet (carteira de R$ 500 mil). Priorizar o P21 (cinema), que é cultural.
A24: P20 | B24: Jovens do Fut – formação em Juatuba | C24: Esporte com cultura | D24: A definir | E24: A confirmar | F24: 500000 | G24: 90000 | H24: ='P20 Jovens do Fut – formação em'!B20 -> 499996.98 | I24: =H24-F24 -> -3.02 | J24: ='P20 Jovens do Fut – formação em'!B16 -> 396823 | K24: ='P20 Jovens do Fut – formação em'!C17 -> 0.06 | L24: ='P20 Jovens do Fut – formação em'!C18 -> 0.1 | M24: ='P20 Jovens do Fut – formação em'!C19 -> 0.1 | N24: =IF(AND('P20 Jovens do Fut – formação em'!E17="OK",'P20 Jovens do Fut – formação em'!E18="OK",'P20 Jovens do Fut – formação em'!E19="OK",'P20 Jovens do Fut – formação em'!E22="OK"),"OK","EXCEDE") -> OK | O24: [REFORMULAÇÃO] Escola de Audiovisual e Narração do Futebol: 6 turmas de 20 jovens (audiovisual/fotografia e narração/podcast), 60 h cada – Audiovisual / Ações de capacitação e treinamento de pessoal | P24: Art. 18 | Q24: 0 | R24: 16 | S24: 5 | T24: 2 | U24: Não submeter como está | V24: • O documento atual (escola de futebol, formato LIE) NÃO pode ser submetido à Rouanet. A planilha esportiva original (R$ 1,13 mi) não é aceitável (IN art. 18; sem segmento no Anexo IV). • A planilha SALIC anexa é uma PROPOSTA DE REFORMULAÇÃO DE OBJETO (formação cultural nas linguagens do futebol). Exige escrever um projeto novo (objetivos, justificativa cultural, projeto pedagógico com carga horária e conteúdo, ficha técnica de arte-educadores) antes de 31/10/2026. • Proponente 'a definir': escolher PJ com CNAE cultural compatível com Audiovisual e portfólio cultural (R$ 500 mil > R$ 200 mil), ou PF com carteira livre. Sem isso não há submissão. • Escolas, CRAS e prefeitura de Juatuba: anuência para salas e para as superfícies dos murais.
A25: P21 | B25: Caravana Cultura & Saúde | C25: Saúde | D25: Rafael Tose | E25: A confirmar | F25: 450000 | G25: 0 | H25: ='P21 Caravana Cultura & Saúde'!B20 -> 449994.24 | I25: =H25-F25 -> -5.76 | J25: ='P21 Caravana Cultura & Saúde'!B16 -> 351558 | K25: ='P21 Caravana Cultura & Saúde'!C17 -> 0.07 | L25: ='P21 Caravana Cultura & Saúde'!C18 -> 0.11 | M25: ='P21 Caravana Cultura & Saúde'!C19 -> 0.1 | N25: =IF(AND('P21 Caravana Cultura & Saúde'!E17="OK",'P21 Caravana Cultura & Saúde'!E18="OK",'P21 Caravana Cultura & Saúde'!E19="OK",'P21 Caravana Cultura & Saúde'!E22="OK"),"OK","EXCEDE") -> OK | O25: Mostra itinerante de cinema brasileiro – 36 blocos de exibição gratuitos em 6 municípios – Audiovisual / Difusão de acervo e conteúdo audiovisual em diversos meios e suportes | P25: Art. 18 | Q25: 9 | R25: 7 | S25: 5 | T25: 5 | U25: Ajustes importantes | V25: • Natureza jurídica do proponente e carteira: Rafael Tose aparece em P19 (kart, R$ 450 mil) e P21 (R$ 450 mil); como PF só cabe um projeto de R$ 450 mil (teto R$ 500 mil). Decidir qual vai à Rouanet ou usar PJ com CNAE audiovisual. • Portfólio cultural/audiovisual comprovável (obrigatório acima de R$ 200 mil); sem ele, trocar o proponente (ex.: produtora AV parceira) ou reduzir a ≤ R$ 200 mil se for 1º projeto. • Seleção dos 6 municípios e espaços (principais + alternativos cobertos) com anuência das prefeituras. • Lista indicativa de filmes com licenças, classificação e versões acessíveis (AD/LSE).
B26: TOTAL | F26: =SUM(F5:F25) -> 9550000 | G26: =SUM(G5:G25) -> 1810000 | H26: =SUM(H5:H25) -> 9549091 | I26: =SUM(I5:I25) -> -908.97

Sheet Carteira por proponente
A1: Limites de carteira por proponente (IN 29, arts. 10, 11 e 15)
A2: Soma só os projetos deste lote; projetos já ativos no SALIC também contam. 'A confirmar' é testado como pessoa física (pior caso). Sócios/dirigentes em comum unem carteiras (art. 15).
A4: Titular | B4: Tipo | C4: Projetos no lote | D4: Qtd. projetos | E4: Valor total orçado (R$) | F4: Limite de carteira (R$) | G4: Qtd. máx. | H4: Situação | I4: Observação
A5: A definir | B5: A confirmar | C5: P20 | D5: 1 | E5: =Resumo!H24 -> 499996.98 | F5: ='Parâmetros IN 29'!$B$8 -> 500000 | G5: 2 | H5: =IF(AND(E5<=F5,D5<=G5),"OK","EXCEDE")&IF(AND(E5<=F5,D5<=G5),""," (se PF)") -> OK | I5: Proponente não definido – projeto não pode ser cadastrado.
A6: Ado Viana | B6: PF | C6: P05, P16 | D6: 2 | E6: =Resumo!H9+Resumo!H20 -> 499886.13 | F6: ='Parâmetros IN 29'!$B$8 -> 500000 | G6: 2 | H6: =IF(AND(E6<=F6,D6<=G6),"OK","EXCEDE") -> OK | I6: Exatamente no teto PF (2 projetos, R$ 500 mil). A exceção de patrimônio (art. 14) não vale para PF. Nenhum outro projeto ativo pode existir.
A7: Amanda Lourenço | B7: A confirmar | C7: P17 | D7: 1 | E7: =Resumo!H21 -> 199986.9 | F7: ='Parâmetros IN 29'!$B$8 -> 500000 | G7: 2 | H7: =IF(AND(E7<=F7,D7<=G7),"OK","EXCEDE")&IF(AND(E7<=F7,D7<=G7),""," (se PF)") -> OK | I7: Se PF e 1º projeto: R$ 200 mil é exatamente o limite sem portfólio.
A8: Armind | B8: A confirmar | C8: P09 | D8: 1 | E8: =Resumo!H13 -> 699999.84 | F8: ='Parâmetros IN 29'!$B$8 -> 500000 | G8: 2 | H8: =IF(AND(E8<=F8,D8<=G8),"OK","EXCEDE")&IF(AND(E8<=F8,D8<=G8),""," (se PF)") -> EXCEDE (se PF) | I8: Se for PF, R$ 700 mil excede o teto por projeto. Confirmar natureza jurídica. P10 cita a Arminde como proponente nos documentos (Gustavo Ribeiro como representante): mesma carteira.
A9: Aver Mídia | B9: PJ | C9: P02, P15 | D9: 2 | E9: =Resumo!H6+Resumo!H19 -> 849671.75 | F9: ='Parâmetros IN 29'!$B$10 -> 15000000 | G9: 10 | H9: =IF(AND(E9<=F9,D9<=G9),"OK","EXCEDE") -> OK
A10: ESIP | B10: PJ | C10: P13, P14 | D10: 2 | E10: =Resumo!H17+Resumo!H18 -> 649991.51 | F10: ='Parâmetros IN 29'!$B$10 -> 15000000 | G10: 10 | H10: =IF(AND(E10<=F10,D10<=G10),"OK","EXCEDE") -> OK
A11: Educare | B11: PJ | C11: P01, P18 | D11: 2 | E11: =Resumo!H5+Resumo!H22 -> 749703.14 | F11: ='Parâmetros IN 29'!$B$10 -> 15000000 | G11: 10 | H11: =IF(AND(E11<=F11,D11<=G11),"OK","EXCEDE") -> OK
A12: Gustavo Ribeiro | B12: A confirmar | C12: P10 | D12: 1 | E12: =Resumo!H14 -> 499996.16 | F12: ='Parâmetros IN 29'!$B$8 -> 500000 | G12: 2 | H12: =IF(AND(E12<=F12,D12<=G12),"OK","EXCEDE")&IF(AND(E12<=F12,D12<=G12),""," (se PF)") -> OK | I12: Documentos indicam a Arminde como proponente; se Gustavo for dirigente da Armind, P09 + P10 ficam na mesma carteira (art. 15) e há risco de fracionamento/duplicidade.
A13: IHV | B13: PJ | C13: P03 | D13: 1 | E13: =Resumo!H7 -> 199953.87 | F13: ='Parâmetros IN 29'!$B$10 -> 15000000 | G13: 10 | H13: =IF(AND(E13<=F13,D13<=G13),"OK","EXCEDE") -> OK | I13: 1º projeto no SALIC: R$ 200 mil é o limite sem portfólio. Verificar se Ado Viana é dirigente (uniria carteira com PF).
A14: Mobox | B14: PJ | C14: P04, P11 | D14: 2 | E14: =Resumo!H8+Resumo!H15 -> 1699976.6 | F14: ='Parâmetros IN 29'!$B$10 -> 15000000 | G14: 10 | H14: =IF(AND(E14<=F14,D14<=G14),"OK","EXCEDE") -> OK | I14: Festa Junina como patrimônio cultural fica fora dos limites de valor e quantidade da PJ (art. 14, §ú).
A15: Morsa | B15: PJ | C15: P06 | D15: 1 | E15: =Resumo!H10 -> 749993.42 | F15: ='Parâmetros IN 29'!$B$10 -> 15000000 | G15: 10 | H15: =IF(AND(E15<=F15,D15<=G15),"OK","EXCEDE") -> OK
A16: PRO SP | B16: PJ | C16: P08 | D16: 1 | E16: =Resumo!H12 -> 599985.45 | F16: ='Parâmetros IN 29'!$B$10 -> 15000000 | G16: 10 | H16: =IF(AND(E16<=F16,D16<=G16),"OK","EXCEDE") -> OK
A17: Rafael Tose | B17: A confirmar | C17: P19, P21 | D17: 2 | E17: =Resumo!H23+Resumo!H25 -> 899993.96 | F17: ='Parâmetros IN 29'!$B$8 -> 500000 | G17: 2 | H17: =IF(AND(E17<=F17,D17<=G17),"OK","EXCEDE")&IF(AND(E17<=F17,D17<=G17),""," (se PF)") -> EXCEDE (se PF) | I17: P19 + P21 somam R$ 900 mil: viola se PF. P19 (kart) não é enquadrável; manter só P21.
A18: Túlio Gama | B18: PF | C18: P07, P12 | D18: 2 | E18: =Resumo!H11+Resumo!H16 -> 749955.32 | F18: ='Parâmetros IN 29'!$B$8 -> 500000 | G18: 2 | H18: =IF(AND(E18<=F18,D18<=G18),"OK","EXCEDE") -> EXCEDE | I18: P07 + P12 somam R$ 750 mil > R$ 500 mil. Só um vai à Rouanet (planilha do cliente já prevê o outro na LEIC). Recomendado: P07 na Rouanet, P12 na LEIC. Verificar vínculo com Morsa/Educare (art. 15).

Sheet Matriz de campos
A1: Campos do SALIC (A), checklist interno do cliente (B) e perguntas específicas (C) – status por projeto
A2: A12, A14 e A17 (cinza) não são campos próprios do formulário SALIC 2026 – mantidos como boa prática. Detalhes na aba 'Revisão detalhada'.
A3: Código | B3: Campo | C3: P01 | D3: P02 | E3: P03 | F3: P04 | G3: P05 | H3: P06 | I3: P07 | J3: P08 | K3: P09 | L3: P10 | M3: P11 | N3: P12 | O3: P13 | P3: P14 | Q3: P15 | R3: P16 | S3: P17 | T3: P18 | U3: P19 | V3: P20 | W3: P21
A4: A1 | B4: Identificação (nome, proponente, CNPJ/CNAE, área/segmento, Art. 18) | C4: PARCIAL | D4: PARCIAL | E4: PARCIAL | F4: PARCIAL | G4: PARCIAL | H4: PARCIAL | I4: PARCIAL | J4: PARCIAL | K4: PARCIAL | L4: PARCIAL | M4: PARCIAL | N4: PARCIAL | O4: PARCIAL | P4: PARCIAL | Q4: PARCIAL | R4: PARCIAL | S4: PARCIAL | T4: PARCIAL | U4: PARCIAL | V4: AUSENTE | W4: PARCIAL
A5: A2 | B5: Período de execução e prazo de captação | C5: PARCIAL | D5: PARCIAL | E5: PARCIAL | F5: PARCIAL | G5: PARCIAL | H5: PARCIAL | I5: PARCIAL | J5: PARCIAL | K5: PARCIAL | L5: PARCIAL | M5: PARCIAL | N5: PARCIAL | O5: PARCIAL | P5: PARCIAL | Q5: PARCIAL | R5: PARCIAL | S5: PARCIAL | T5: PARCIAL | U5: PARCIAL | V5: PARCIAL | W5: PARCIAL
A6: A3 | B6: Resumo | C6: OK | D6: OK | E6: OK | F6: OK | G6: OK | H6: OK | I6: OK | J6: OK | K6: OK | L6: OK | M6: OK | N6: OK | O6: PARCIAL | P6: OK | Q6: OK | R6: PARCIAL | S6: OK | T6: OK | U6: PARCIAL | V6: PARCIAL | W6: OK
A7: A4 | B7: Objetivos (geral e específicos mensuráveis) | C7: PARCIAL | D7: OK | E7: OK | F7: PARCIAL | G7: PARCIAL | H7: OK | I7: OK | J7: PARCIAL | K7: OK | L7: OK | M7: OK | N7: OK | O7: PARCIAL | P7: OK | Q7: OK | R7: OK | S7: OK | T7: OK | U7: PARCIAL | V7: PARCIAL | W7: OK
A8: A5 | B8: Justificativa (art. 1º/3º Lei 8.313, relevância, dados) | C8: PARCIAL | D8: PARCIAL | E8: PARCIAL | F8: PARCIAL | G8: PARCIAL | H8: PARCIAL | I8: PARCIAL | J8: PARCIAL | K8: PARCIAL | L8: PARCIAL | M8: PARCIAL | N8: PARCIAL | O8: PARCIAL | P8: PARCIAL | Q8: PARCIAL | R8: PARCIAL | S8: PARCIAL | T8: PARCIAL | U8: PARCIAL | V8: PARCIAL | W8: PARCIAL
A9: A6 | B9: Acessibilidade (arquitetônica, comunicacional, divulgação; Guia MDHC) | C9: PARCIAL | D9: PARCIAL | E9: PARCIAL | F9: PARCIAL | G9: PARCIAL | H9: PARCIAL | I9: PARCIAL | J9: PARCIAL | K9: PARCIAL | L9: PARCIAL | M9: PARCIAL | N9: PARCIAL | O9: PARCIAL | P9: PARCIAL | Q9: PARCIAL | R9: PARCIAL | S9: PARCIAL | T9: OK | U9: PARCIAL | V9: PARCIAL | W9: OK
A10: A7 | B10: Democratização de acesso (art. 41) | C10: OK | D10: OK | E10: OK | F10: OK | G10: PARCIAL | H10: OK | I10: OK | J10: PARCIAL | K10: OK | L10: OK | M10: OK | N10: OK | O10: OK | P10: OK | Q10: OK | R10: OK | S10: OK | T10: OK | U10: PARCIAL | V10: PARCIAL | W10: OK
A11: A8 | B11: Ampliação de acesso (art. 42) / contrapartida (art. 44) | C11: PARCIAL | D11: PARCIAL | E11: PARCIAL | F11: OK | G11: PARCIAL | H11: PARCIAL | I11: OK | J11: PARCIAL | K11: OK | L11: PARCIAL | M11: OK | N11: OK | O11: PARCIAL | P11: PARCIAL | Q11: OK | R11: PARCIAL | S11: PARCIAL | T11: PARCIAL | U11: PARCIAL | V11: PARCIAL | W11: PARCIAL
A12: A9 | B12: Etapas de trabalho | C12: OK | D12: OK | E12: OK | F12: OK | G12: OK | H12: OK | I12: OK | J12: OK | K12: OK | L12: OK | M12: OK | N12: OK | O12: PARCIAL | P12: OK | Q12: OK | R12: OK | S12: OK | T12: OK | U12: PARCIAL | V12: PARCIAL | W12: OK
A13: A10 | B13: Ficha técnica | C13: PARCIAL | D13: AUSENTE | E13: AUSENTE | F13: AUSENTE | G13: AUSENTE | H13: AUSENTE | I13: PARCIAL | J13: PARCIAL | K13: AUSENTE | L13: AUSENTE | M13: PARCIAL | N13: PARCIAL | O13: AUSENTE | P13: AUSENTE | Q13: AUSENTE | R13: AUSENTE | S13: AUSENTE | T13: AUSENTE | U13: PARCIAL | V13: PARCIAL | W13: AUSENTE
A14: A11 | B14: Sinopse/descrição do conteúdo artístico | C14: PARCIAL | D14: PARCIAL | E14: PARCIAL | F14: AUSENTE | G14: PARCIAL | H14: PARCIAL | I14: PARCIAL | J14: PARCIAL | K14: PARCIAL | L14: PARCIAL | M14: PARCIAL | N14: PARCIAL | O14: AUSENTE | P14: PARCIAL | Q14: PARCIAL | R14: PARCIAL | S14: PARCIAL | T14: PARCIAL | U14: AUSENTE | V14: AUSENTE | W14: PARCIAL
... A40: C5 | B40: Pergunta específica 5 (ver Revisão detalhada) | C40: OK | D40: PARCIAL | E40: PARCIAL | F40: PARCIAL | G40: PARCIAL | H40: PARCIAL | I40: OK | J40: OK | K40: PARCIAL | L40: AUSENTE | M40: OK | N40: PARCIAL | O40: PARCIAL | P40: PARCIAL | Q40: PARCIAL | R40: OK | S40: PARCIAL | T40: PARCIAL | U40: PARCIAL | V40: PARCIAL | W40: PARCIAL
B42: Total OK | C42: =COUNTIF(C4:C40,"OK") -> 13 | D42: =COUNTIF(D4:D40,"OK") -> 14 | E42: =COUNTIF(E4:E40,"OK") -> 15 | F42: =COUNTIF(F4:F40,"OK") -> 12 | G42: =COUNTIF(G4:G40,"OK") -> 7 | H42: =COUNTIF(H4:H40,"OK") -> 13 | I42: =COUNTIF(I4:I40,"OK") -> 13 | J42: =COUNTIF(J4:J40,"OK") -> 7 | ... W42: =COUNTIF(W4:W40,"OK") -> 16
B43: Total PARCIAL | C43: =COUNTIF(C4:C40,"PARCIAL") -> 21 | D43: =COUNTIF(D4:D40,"PARCIAL") -> 19 | E43: =COUNTIF(E4:E40,"PARCIAL") -> 18 | F43: =COUNTIF(F4:F40,"PARCIAL") -> 21 | G43: =COUNTIF(G4:G40,"PARCIAL") -> 21 | H43: =COUNTIF(H4:H40,"PARCIAL") -> 18 | I43: =COUNTIF(I4:I40,"PARCIAL") -> 21 | J43: =COUNTIF(J4:J40,"PARCIAL") -> 28 | ... W43: =COUNTIF(W4:W40,"PARCIAL") -> 13
B44: Total AUSENTE | C44: =COUNTIF(C4:C40,"AUSENTE") -> 3 | D44: =COUNTIF(D4:D40,"AUSENTE") -> 4 | E44: =COUNTIF(E4:E40,"AUSENTE") -> 4 | F44: =COUNTIF(F4:F40,"AUSENTE") -> 4 | G44: =COUNTIF(G4:G40,"AUSENTE") -> 9 | H44: =COUNTIF(H4:H40,"AUSENTE") -> 6 | I44: =COUNTIF(I4:I40,"AUSENTE") -> 3 | J44: =COUNTIF(J4:J40,"AUSENTE") -> 2 | ... W44: =COUNTIF(W4:W40,"AUSENTE") -> 8

Sheet Revisão detalhada
A1: Revisão campo a campo (use o filtro da coluna Projeto)
A3: Projeto | B3: Bloco | C3: Código | D3: Campo / pergunta | E3: Status | F3: O que o documento traz | G3: O que falta / ajuste
A4: P01 Escola de Ofícios do Espetáculo | B4: SALIC | C4: A1 | D4: Identificação (nome, proponente, CNPJ/CNAE, área/segmento, Art. 18) | E4: PARCIAL | F4: Nome e proponente Educare Formação e Desenvolvimento LTDA, CNPJ 44.799.592/0001-29; mecanismos Rouanet + LEIC. O texto alterna 'Educare', 'Educari' e 'Educação'. | G4: Declarar área Artes Cênicas / segmento Empreend Ações Educ-Cult/Capacitação/Treinamento e pedido de Art. 18; conferir no cartão CNPJ se há CNAE cultural compatível (ex.: 85.92-9/99 ensino de arte e cultura; 90.01-9/99) – razão social 'Formação e Desenvolvimento' sugere CNAE de treinamento (85.99), o que pode barrar a admissibilidade (art. 4º §3º); padronizar o nome 'Educare'.
A5: P01 Escola de Ofícios do Espetáculo | B5: SALIC | C5: A2 | D5: Período de execução e prazo de captação | E5: PARCIAL | F5: Ago–nov/2027 com 'preparação anterior e encerramento posterior' sem datas. | G5: Fixar datas (sugestão: 01/06/2027 a 31/12/2027) e prazo de captação; o cronograma precisa casar com a planilha (pré jun–jul, produção ago–nov, pós dez).
A6: P01 Escola de Ofícios do Espetáculo | B6: SALIC | C6: A3 | D6: Resumo | E6: OK | F6: Item 1 'Apresentação' e item 2 'Objeto' descrevem o projeto de forma clara. | G6: Condensar em resumo único para o campo do SALIC, citando 270 vagas, 9 turmas, 3 núcleos, 24h e mostra.
A7: P01 Escola de Ofícios do Espetáculo | B7: SALIC | C7: A4 | D7: Objetivos (geral e específicos mensuráveis) | E7: PARCIAL | F7: Objetivo geral e 8 específicos; vários com 'sempre que possível'/'aproximadamente'. | G7: Tornar mensuráveis: nº de visitas (9), taxa mínima de conclusão (ex.: 70%), público da mostra (número fechado), % de educadores dos territórios.
A8: P01 Escola de Ofícios do Espetáculo | B8: SALIC | C8: A5 | D8: Justificativa (art. 1º/3º Lei 8.313, relevância, dados) | E8: PARCIAL | F8: Justificativa qualitativa consistente (bastidores invisibilizados, descentralização, mostra). | G8: Incluir dados (ex.: oferta de formação técnica em artes cênicas em BH/RMBH, IVS dos territórios) e citar expressamente art. 1º (I, II) e art. 3º, I, 'c'/'d' da Lei 8.313/91 (formação e acesso).
A9: P01 Escola de Ofícios do Espetáculo | B9: SALIC | C9: A6 | D9: Acessibilidade (arquitetônica, comunicacional, divulgação; Guia MDHC) | E9: PARCIAL | F9: Item 12 lista diretrizes genéricas: Libras 'quando o perfil demandar', materiais 'sempre que necessário', atenção a autistas. | G9: Transformar em medidas fixas e orçadas: Libras em aulas inaugurais, visitas e mostra; audiodescrição na mostra; materiais ampliados/braille; consultor de acessibilidade; vídeo com Libras/AD; citar uso obrigatório do Guia MDHC (art. 40). Pendência MÉDIA 5 continua aberta.
A10: P01 Escola de Ofícios do Espetáculo | B10: SALIC | C10: A7 | D10: Democratização de acesso (art. 41) | E10: OK | F10: Item 13: 100% gratuito, inscrições públicas, prioridade socioeconômica/territorial e escola pública; mostra gratuita. | G10: Definir percentual de vagas reservadas (ex.: ≥50% estudantes de escola pública) e fluxo de seleção objetivo (pendência MÉDIA 6).
A11: P01 Escola de Ofícios do Espetáculo | B11: SALIC | C11: A8 | D11: Ampliação de acesso (art. 42) / contrapartida (art. 44) | E11: PARCIAL | F11: Visitas técnicas e mostra existem, mas nenhuma medida do art. 42 é declarada. Sem venda: contrapartida do art. 44 não se aplica. | G11: Declarar ao menos: art. 42, VI (ação para adolescentes/jovens e educadores) e III (vídeo-memória online com Libras e audiodescrição) – ambas já orçadas.
A12: P01 Escola de Ofícios do Espetáculo | B12: SALIC | C12: A9 | D12: Etapas de trabalho | E12: OK | F12: Item 18 – cronograma macro (pré-execução, ago, set, out, nov, pós). | G12: Detalhar entregas por mês e responsáveis; alinhar às etapas da planilha.
A13: P01 Escola de Ofícios do Espetáculo | B13: SALIC | C13: A10 | D13: Ficha técnica | E13: PARCIAL | F13: Coord. geral Túlio Gama; coord. pedagógica Jade Oliveira; coord. técnica e educadores 'a definir'. | G13: Nomear coordenador técnico e ao menos 1 educador por eixo; anexar currículos (Anexo II 3.1); confirmar vínculo de Túlio Gama com a Educare (art. 15 e 23).
A14: P01 Escola de Ofícios do Espetáculo | B14: SALIC | C14: A11 | D14: Sinopse/descrição do conteúdo artístico | E14: PARCIAL | F14: Ementas por eixo (item 8) e descrição da mostra (item 11). | G14: Definir o espetáculo/grupo parceiro da mostra (sinopse, duração, classificação, autorização do autor).
... A40: P01 Escola de Ofícios do Espetáculo | B40: Pergunta específica | C40: C5 | D40: Como será avaliada a aprendizagem? Haverá montagem prática, apresentação final, certificação ou aproximação com oportunidades de trabalho? | E40: OK | F40: Frequência mínima 60%, avaliação dos educadores e participação na mostra; certificado da Educare; sem promessa de inserção profissional. | G40: Instrumentos de avaliação (ficha do educador, questionário) – pendência MÉDIA 7.
A41: P01 Escola de Ofícios do Espetáculo | B41: Conformidade IN 29 | D41: Limite por projeto e carteira PJ (arts. 10–11) | E41: OK | F41: R$ 500 mil ≤ R$ 1,5 mi; carteira Educare = P01 R$ 500 mil + P18 R$ 250 mil = R$ 750 mil, 2 projetos.
A42: P01 Escola de Ofícios do Espetáculo | B42: Conformidade IN 29 | D42: CNAE cultural compatível (art. 4º §3º) | E42: ATENÇÃO | F42: Razão social 'Formação e Desenvolvimento' indica CNAE de treinamento; se não houver CNAE cultural (ex.: 85.92-9/99, 90.01-9/99) o SALIC bloqueia. Incluir CNAE secundário antes do cadastro, se necessário.
A43: P01 Escola de Ofícios do Espetáculo | B43: Conformidade IN 29 | D43: Portfólio (art. 4º §4º/§5º; Anexo II 1.1) | E43: ATENÇÃO | F43: Valor > R$ 200 mil: portfólio cultural obrigatório. Pendência ALTA 2 em aberto.
A44: P01 Escola de Ofícios do Espetáculo | B44: Conformidade IN 29 | D44: Mesma carteira (art. 15) e remuneração do proponente (art. 23) | E44: ATENÇÃO | F44: Túlio Gama (coord. geral) é proponente PF de P07/P12. Se for sócio/dirigente da Educare, as carteiras se unem e os pagamentos a ele contam no limite de 20% do proponente; confirmar quadro societário.
A45: P01 Escola de Ofícios do Espetáculo | B45: Conformidade IN 29 | D45: Fracionamento (art. 32, VII; Anexo I XXXIII) | E45: ATENÇÃO | F45: Objetos próximos no portfólio: P03 (oficinas de música/grafite/audiovisual para jovens de vilas de BH/Contagem – IHV) e P18 (Educare – idosos). Objetivos e públicos diferem e nenhum limite é ultrapassado; manter redações e territórios distintos e não usar o eixo audiovisual de forma idêntica ao P03.
A46: P01 Escola de Ofícios do Espetáculo | B46: Conformidade IN 29 | D46: Art. 18 da IN (projetos educativos/sociais: só custos artístico-culturais) | E46: ATENÇÃO | F46: Planilha contém apenas custos culturais; lanche e transporte coletivo estão vinculados às atividades. Não incluir bolsas, auxílios individuais ou promessas de emprego.
A47: P01 Escola de Ofícios do Espetáculo | B47: Conformidade IN 29 | D47: Custos vinculados e captação (arts. 19, 20, 22) | E47: OK | F47: Adm 8,5%, acessibilidade/divulgação 17,8%, captação 10% (R$ 36.670) do valor do projeto (R$ 366.700).
A48: P01 Escola de Ofícios do Espetáculo | B48: Conformidade IN 29 | D48: Limite de 20% por fornecedor (art. 24) | E48: OK | F48: Maior fornecedor potencial (locação de luz/som e ônibus) < R$ 60 mil (12%). Se Armind fornecer toda a luz, conferir o teto.
A49: P01 Escola de Ofícios do Espetáculo | B49: Conformidade IN 29 | D49: Cachês (art. 26) | E49: OK | F49: Direção R$ 10 mil (individual) e grupo R$ 8 mil – abaixo dos tetos.
A50: P01 Escola de Ofícios do Espetáculo | B50: Conformidade IN 29 | D50: Acessibilidade obrigatória e Guia MDHC (arts. 38–40) | E50: ATENÇÃO | F50: Texto genérico; a planilha prevê recursos concretos – atualizar o texto.
A51: P01 Escola de Ofícios do Espetáculo | B51: Conformidade IN 29 | D51: Democratização (art. 41) / ampliação (art. 42) / contrapartida (art. 44) | E51: ATENÇÃO | F51: 100% gratuito (OK); falta declarar a medida do art. 42 (sugestão VI + III); art. 44 não se aplica (sem venda).
A52: P01 Escola de Ofícios do Espetáculo | B52: Conformidade IN 29 | D52: Direito autoral do texto da mostra (Anexo II 3.3; art. 27) | E52: ATENÇÃO | F52: Grupo/espetáculo da mostra não definido – anexar autorização do autor ou usar texto em domínio público/criação coletiva.
... A54: P01 Escola de Ofícios do Espetáculo | B54: Conformidade IN 29 | D54: Prazo de apresentação (art. 5º – até 31/10) | E54: ATENÇÃO | F54: Faltam 17 dias (hoje 14/10/2026) e as pendências ALTA 1, 2, 4, 8 e 9 seguem abertas.
A55: P02 Mestres e Aprendizes | B55: SALIC | C55: A1 | D55: Identificação (nome, proponente, CNPJ/CNAE, área/segmento, Art. 18) | E55: PARCIAL | F55: Título, Aver Mídia Produções LTDA, CNPJ 46.152.875/0001-00; enquadramento preliminar Patrimônio/Salvaguarda, 'pretendido art. 18'. | G55: Confirmar CNAE compatível com Patrimônio Cultural (produtora audiovisual pode não ter CNAE correspondente – art. 4º §3º); fechar segmento definitivo (pendência ALTA 5).
A56: P02 Mestres e Aprendizes | B56: SALIC | C56: A2 | D56: Período de execução e prazo de captação | E56: PARCIAL | F56: 8 meses: jul/2027 a fev/2028, com correspondência mês a mês. | G56: Datas exatas e prazo de captação.
A57: P02 Mestres e Aprendizes | B57: SALIC | C57: A3 | D57: Resumo | E57: OK | F57: Item 3 'Resumo' completo; item 28 traz texto para o produto principal. | G57: —
A58: P02 Mestres e Aprendizes | B58: SALIC | C58: A4 | D58: Objetivos | E58: OK | F58: Objetivo geral e 10 específicos quantificados (4 mestres, 120 vagas, 24 encontros, 48h, 1 exposição). | G58: Incluir meta de conclusão (frequência mínima).
A59: P02 Mestres e Aprendizes | B59: SALIC | C59: A5 | D59: Justificativa | E59: PARCIAL | F59: Justificativa conceitual forte (transmissão pela convivência, remuneração e reconhecimento dos mestres, intergeracionalidade). | G59: Dados e histórico de cada saber/bem (depende dos mestres), citar art. 1º e art. 3º (II e IV) da Lei 8.313 e aderência à salvaguarda (Decreto 3.551/2000).
A60: P02 Mestres e Aprendizes | B60: SALIC | C60: A6 | D60: Acessibilidade | E60: PARCIAL | F60: Item 15: critérios físicos, linguagem clara, legendas, descrição de imagens; Libras/AD 'conforme necessidades'. | G60: Fixar recursos: Libras em acolhimento/integrados/abertura, AD e recursos táteis na exposição, consultor; citar Guia MDHC.
A61: P02 Mestres e Aprendizes | B61: SALIC | C61: A7 | D61: Democratização de acesso | E61: OK | F61: 100% gratuito, apoio presencial à inscrição, catálogo digital gratuito, critérios transparentes. | G61: Fixar proporção de vagas reservadas a escolas/comunidades (pendência MÉDIA 10).
A62: P02 Mestres e Aprendizes | B62: SALIC | C62: A8 | D62: Ampliação de acesso (art. 42) / contrapartida (art. 44) | E62: PARCIAL | F62: Medidas implícitas (exposição gratuita, catálogo digital, jovens a partir de 12 anos). Sem venda: art. 44 não se aplica. | G62: Declarar art. 42, I (doação de 10% do catálogo), III (vídeos com Libras/AD) e/ou VI (ação para adolescentes/jovens e educadores).
A63: P02 Mestres e Aprendizes | B63: SALIC | C63: A9 | D63: Etapas de trabalho | E63: OK | F63: Item 13: Etapas 1–4 com atividades; item 22 cronograma de 14 atividades. | G63: —
A64: P02 Mestres e Aprendizes | B64: SALIC | C64: A10 | D64: Ficha técnica | E64: AUSENTE | F64: Todas as funções 'nome a definir', inclusive os 4 mestres. | G64: Nomes e currículos de coordenação, curadoria e mestres; experiência junto às comunidades (Anexo II 8.1.6).
A65: P02 Mestres e Aprendizes | B65: SALIC | C65: A11 | D65: Descrição do conteúdo/bens culturais | E65: PARCIAL | F65: Saberes de referência (bordado, cerâmica, bonecos, viola) 'não definitivos'. | G65: Identificar cada bem/saber, seu território e detentores.
A66: P02 Mestres e Aprendizes | B66: SALIC | C66: A12 | D66: Impacto ambiental – NÃO é campo do SALIC 2026 (opcional em 'Outras informações') | E66: OK | F66: Item 12: dimensionar insumos, reutilização, descarte e armazenamento seguros. | G66: Detalhar destino de resíduos de cerâmica/tintas.
... A91: P02 Mestres e Aprendizes | B91: Pergunta específica | C91: C5 | D91: Haverá apresentação, exposição ou registro dos saberes? Como serão definidos remuneração, créditos, autorizações e conteúdos que podem ser divulgados? | E91: PARCIAL | F91: Exposição gratuita, catálogo, acervo e vídeos; mestres creditados como detentores; não divulgação de saberes restritos; autorizações específicas. | G91: Memória de cálculo da remuneração (adotada aqui: R$ 2.800/mês por mestre + cachês de concepção e abertura), termos e ficha de limites de registro (pendência 16).
...

Sheet Enquadramento e pendências
A1: Enquadramento Art. 18, pendências críticas e recomendações por projeto
A3: Projeto | B3: Produto principal e secundários | C3: Área / segmento (Anexo IV) | D3: Enquadr. | E3: Análise de enquadramento | F3: Pendências críticas | G3: Recomendações | H3: Versão mínima
A4: P01 Escola de Ofícios do Espetáculo | B4: Curso/Oficina – ciclo formativo de iniciação aos ofícios técnicos e criativos das artes cênicas (9 turmas x 24h, 270 vagas, 3 núcleos) Secundários: – Mostra final integrada – apresentação teatral com figurino, maquiagem, luz e vídeo realizados pelos participantes (1 sessão gratuita) (Artes Cênicas / Apresentação ou Performance de Teatro) | C4: Artes Cênicas / Empreend Ações Educ-Cult/Capacitação/Treinamento | D4: Art. 18 | E4: Produto principal = oficinas (R$ ~300 mil das etapas de projeto, muito acima da mostra, ~R$ 52 mil), logo o enquadramento segue Artes Cênicas > 'Empreend Ações Educ-Cult/Capacitação/Treinamento' = Art. 18 (Anexo IV). Riscos: (1) o eixo Audiovisual pode levar o técnico a sugerir área Audiovisual – também Art. 18 ('Ações de capacitação e treinamento de pessoal'), mas convém redigi-lo como 'audiovisual integrado à cena/registro do espetáculo' para manter um único segmento cênico; (2) a mostra NÃO deve ser um show de música popular cantada (Art. 26) – escolher grupo TEATRAL (a proposta admite 'teatral ou musical'); como secundário não muda o enquadramento, mas evita questionamento; (3) o caráter 'social/educativo' (público vulnerável) atrai o art. 18 da IN: somente custos artístico-culturais – não incluir bolsas-auxílio, vale-transporte individual, inclusão produtiva ou promessa de empregabilidade (a própria proposta já veda isso – manter); (4) não chamar de 'curso técnico/profissionalizante' (evita leitura de educação formal). Redação recomendada no SALIC: 'Ações educativo-culturais de iniciação aos ofícios do espetáculo cênico (figurino, caracterização, iluminação cênica e audiovisual para a cena), com mostra cênica de culminância'. | F4: • Documentação jurídica da Educare (cartão CNPJ com CNAE cultural compatível, contrato social, representante) – sem isso o SALIC não admite. • Portfólio de atuação cultural da Educare (obrigatório para projeto de R$ 500 mil). • Projeto pedagógico formal com currículo da coordenadora pedagógica e plano de execução com carga horária e conteúdo programático por turma (Anexo II 7.2/7.3), incluindo a matriz núcleo x formação. • Cartas de anuência dos 3 núcleos e do local da mostra; definição do grupo teatral parceiro com autorização autoral. • Adotar a planilha orçamentária e transformar a acessibilidade em medidas concretas (Libras, AD, consultor, Guia MDHC). | G4: • Cadastrar como Artes Cênicas > Empreend Ações Educ-Cult/Capacitação/Treinamento (Art. 18), produto principal 'Curso/Oficina', e a mostra como produto secundário 'Apresentação ou Performance de Teatro'. • Padronizar o nome do proponente (Educare) em todo o texto; remover 'Educari'/'Educação'. • Declarar matriz sugerida: Iluminação 3 turmas, Audiovisual 2, Figurino 2, Maquiagem 2 (premissa da planilha) – ajustar se a matriz já fechada for diferente. • Escolher grupo TEATRAL (não show musical) para a mostra, evitando leitura de música popular cantada. • Declarar art. 42, VI e III como medidas de ampliação e publicar o vídeo-memória com Libras e AD. • Confirmar se Túlio Gama tem vínculo societário com a Educare (art. 15/23) e registrar no SALIC. • Ajustar o cronograma: pré jun–jul/2027, oficinas ago–nov, pós dez/2027; captação aberta desde a portaria. | H4: R$ 100.000: Reduzir para 1 núcleo (central, ex.: CRJ) com 3 turmas (iluminação, figurino/maquiagem combinados e audiovisual) = 90 vagas, mantendo 24h por turma; eliminar coordenação técnica e assistente de produção (coordenação pedagógica acumula), reduzir coordenação geral para 4 meses em dedicação parcial; 3 visitas técnicas (1 ônibus por turma); mostra simplificada no próprio núcleo com grupo parceiro e luz/som pequeno porte; manter Libras na aula inaugural e na mostra, AD na mostra e vídeo com Libras; comunicação apenas digital + cartazes. Custos vinculados proporcionais (adm ~8%, acessibilidade/divulgação ~15%, captação 10%).
